[06/27 17:31:38] cvalgorithms INFO: Starting training from iteration 0
[06/27 17:31:51] cvalgorithms ERROR: Exception during training:
Traceback (most recent call last):
  File "C:\Users\user1\PycharmProjects\cvalgorithms\utils\events.py", line 345, in _get_eta
    eta_seconds = storage.history("time").median(1000) * (self._max_iter - iteration - 1)
  File "C:\Users\user1\PycharmProjects\cvalgorithms\utils\events.py", line 207, in history
    raise KeyError("No history metric available for {}!".format(name))
KeyError: 'No history metric available for time!'

During handling of the above exception, another exception occurred:

Traceback (most recent call last):
  File "C:\Users\user1\PycharmProjects\cvalgorithms\trainer\tools\runner.py", line 124, in train
    self.after_step()
  File "C:\Users\user1\PycharmProjects\cvalgorithms\trainer\tools\runner.py", line 146, in after_step
    h.after_step()
  File "C:\Users\user1\PycharmProjects\cvalgorithms\trainer\hooks\hooks.py", line 301, in after_step
    writer.write()
  File "C:\Users\user1\PycharmProjects\cvalgorithms\utils\events.py", line 378, in write
    eta_string = self._get_eta(storage)
  File "C:\Users\user1\PycharmProjects\cvalgorithms\utils\events.py", line 353, in _get_eta
    iteration - self._last_write[0]
ZeroDivisionError: float division by zero
[06/27 17:45:29] cvalgorithms INFO: Starting training from iteration 0
[06/27 17:45:33] cvalgorithms INFO:  iter: 0  total_loss: 323.9  decode.loss_seg: 0  aux_0.loss: 0  cnt.cnt_loss: 161.9  loss: 161.9  data_time: 0.0886  lr: N/A  max_mem: 3221M
[06/27 17:45:34] cvalgorithms ERROR: Exception during training:
Traceback (most recent call last):
  File "C:\Users\user1\PycharmProjects\cvalgorithms\utils\events.py", line 345, in _get_eta
    eta_seconds = storage.history("time").median(1000) * (self._max_iter - iteration - 1)
  File "C:\Users\user1\PycharmProjects\cvalgorithms\utils\events.py", line 207, in history
    raise KeyError("No history metric available for {}!".format(name))
KeyError: 'No history metric available for time!'

During handling of the above exception, another exception occurred:

Traceback (most recent call last):
  File "C:\Users\user1\PycharmProjects\cvalgorithms\trainer\tools\runner.py", line 124, in train
    self.after_step()
  File "C:\Users\user1\PycharmProjects\cvalgorithms\trainer\tools\runner.py", line 146, in after_step
    h.after_step()
  File "C:\Users\user1\PycharmProjects\cvalgorithms\trainer\hooks\hooks.py", line 301, in after_step
    writer.write()
  File "C:\Users\user1\PycharmProjects\cvalgorithms\utils\events.py", line 378, in write
    eta_string = self._get_eta(storage)
  File "C:\Users\user1\PycharmProjects\cvalgorithms\utils\events.py", line 353, in _get_eta
    iteration - self._last_write[0]
ZeroDivisionError: float division by zero
[06/27 17:48:07] cvalgorithms INFO: Starting training from iteration 0
[06/27 17:58:25] cvalgorithms INFO: Starting training from iteration 0
[06/27 17:58:29] cvalgorithms INFO:  iter: 0  total_loss: 118.6  decode.loss_seg: -5.333e-06  aux_0.loss: 1.415e-06  cnt.cnt_loss: 59.3  loss: 59.3  data_time: 0.0816  lr: N/A  max_mem: 3221M
[06/27 17:58:30] cvalgorithms ERROR: Exception during training:
Traceback (most recent call last):
  File "C:\Users\user1\PycharmProjects\cvalgorithms\utils\events.py", line 345, in _get_eta
    eta_seconds = storage.history("time").median(1000) * (self._max_iter - iteration - 1)
  File "C:\Users\user1\PycharmProjects\cvalgorithms\utils\events.py", line 207, in history
    raise KeyError("No history metric available for {}!".format(name))
KeyError: 'No history metric available for time!'

During handling of the above exception, another exception occurred:

Traceback (most recent call last):
  File "C:\Users\user1\PycharmProjects\cvalgorithms\trainer\tools\runner.py", line 122, in train
    self.after_step()
  File "C:\Users\user1\PycharmProjects\cvalgorithms\trainer\tools\runner.py", line 144, in after_step
    h.after_step()
  File "C:\Users\user1\PycharmProjects\cvalgorithms\trainer\hooks\hooks.py", line 301, in after_step
    writer.write()
  File "C:\Users\user1\PycharmProjects\cvalgorithms\utils\events.py", line 378, in write
    eta_string = self._get_eta(storage)
  File "C:\Users\user1\PycharmProjects\cvalgorithms\utils\events.py", line 353, in _get_eta
    iteration - self._last_write[0]
ZeroDivisionError: float division by zero
